Workbook

Sheet Dashboard
B2: Food & Fitness Dashboard — October 2026
B3: Overview of nutrition, exercise, and weight progress. Data sourced from Food Log, Exercise Log, and Weight Log tabs.
B5: =COUNTIF('Dashboard Data'!K7:K37,">"&0) | D5: =IFERROR(AVERAGEIF('Dashboard Data'!D7:D37,">"&0),0) | F5: =IFERROR(AVERAGEIF('Dashboard Data'!E7:E37,">"&0),0) | H5: =IFERROR(AVERAGEIF('Dashboard Data'!J7:J37,">"&0),0) | J5: =IFERROR(AVERAGEIF('Dashboard Data'!G7:G37,">"&0),0) | L5: ='Weight Log'!C9
B6: Days Logged | D6: Avg Health Score | F6: Avg Protein/day | H6: Avg Calories/day | J6: Avg Fibre/day | L6: Current Weight
B8: Weight Goal | E8: Nutrition vs Ideal | J8: Exercise This Month
B9: Start | C9: ='Weight Log'!C6 | E9: Nutrient | F9: Yours | G9: Ideal | H9: % Met | J9: Total Calories Burned | K9: =SUM('Dashboard Data'!D42:D72)
B10: Target | C10: ='Weight Log'!C7 | E10: ='Dashboard Data'!C77 | F10: ='Dashboard Data'!D77 | G10: ='Dashboard Data'!E77 | H10: ='Dashboard Data'!F77 | J10: Total Duration (min) | K10: =SUM('Dashboard Data'!E42:E72)
B11: Current | C11: ='Weight Log'!C9 | E11: ='Dashboard Data'!C78 | F11: ='Dashboard Data'!D78 | G11: ='Dashboard Data'!E78 | H11: ='Dashboard Data'!F78 | J11: Total Steps | K11: =SUM('Dashboard Data'!F42:F72)
B12: Change | C12: ='Weight Log'!C10 | E12: ='Dashboard Data'!C79 | F12: ='Dashboard Data'!D79 | G12: ='Dashboard Data'!E79 | H12: ='Dashboard Data'!F79 | J12: Active Days | K12: =COUNTIF('Dashboard Data'!D42:D72,">"&0)
B13: Progress | C13: ='Weight Log'!C11 | E13: ='Dashboard Data'!C80 | F13: ='Dashboard Data'!D80 | G13: ='Dashboard Data'!E80 | H13: ='Dashboard Data'!F80
E14: ='Dashboard Data'!C81 | F14: ='Dashboard Data'!D81 | G14: ='Dashboard Data'!E81 | H14: ='Dashboard Data'!F81

Sheet Food Log
B2: Food Log — October 2026
B3: Log every meal below. The cron job will estimate Protein, Carbs, Fibre, Vitamins, and Calories from the Food Item.
B5: Healthiness (1-5): 1 = Junk/fried · 2 = Mostly unhealthy · 3 = Mixed/okay · 4 = Mostly healthy · 5 = Very healthy/home-cooked | Vitamins (1-5): 1 = No fruit/veg · 3 = Some · 5 = Very vitamin-rich
B7: Date | C7: Meal | D7: Food Item | E7: Healthiness (1-5) | F7: Protein (g) | G7: Carbs (g) | H7: Fibre (g) | I7: Fat (g) | J7: Vitamins (1-5) | K7: Calories (kcal) | L7: Notes
B8: 46296 | C8: Breakfast | D8: Poha with peanuts & vegetables | E8: 4 | F8: 8 | G8: 42 | H8: 5 | I8: 6 | J8: 3 | K8: 290
B9: 46296 | C9: Lunch | D9: Dal tadka, jeera rice, bhindi sabzi | E9: 5 | F9: 16 | G9: 68 | H9: 9 | I9: 8 | J9: 4 | K9: 520 | L9: Home cooked
B10: 46296 | C10: Snack | D10: Chai + 2 parle-g biscuits | E10: 2 | F10: 2 | G10: 18 | H10: 0 | I10: 3 | J10: 1 | K10: 120
B11: 46296 | C11: Dinner | D11: Paneer butter masala, 2 roti | E11: 3 | F11: 18 | G11: 55 | H11: 4 | I11: 16 | J11: 2 | K11: 580 | L11: Swiggy order
B12: 46297 | C12: Breakfast | D12: Idli (3) with sambar & chutney | E12: 5 | F12: 9 | G12: 52 | H12: 6 | I12: 3 | J12: 3 | K12: 310
B13: 46297 | C13: Lunch | D13: Chicken curry, rice, raita | E13: 4 | F13: 28 | G13: 72 | H13: 4 | I13: 14 | J13: 3 | K13: 650 | L13: Home cooked
B14: 46297 | C14: Snack | D14: Apple + handful of almonds | E14: 5 | F14: 6 | G14: 18 | H14: 4 | I14: 14 | J14: 5 | K14: 220
B15: 46297 | C15: Dinner | D15: Egg fried rice, manchurian | E15: 2 | F15: 14 | G15: 78 | H15: 3 | I15: 18 | J15: 2 | K15: 720 | L15: Street food
B16: 46298 | C16: Breakfast | D16: Masala dosa + filter coffee | E16: 4 | F16: 7 | G16: 48 | H16: 3 | I16: 8 | J16: 2 | K16: 350
B17: 46298 | C17: Lunch | D17: Rajma chawal, salad | E17: 5 | F17: 14 | G17: 65 | H17: 12 | I17: 6 | J17: 4 | K17: 480 | L17: Home cooked
B18: 46298 | C18: Dinner | D18: Maggi noodles + boiled egg | E18: 2 | F18: 10 | G18: 52 | H18: 2 | I18: 8 | J18: 1 | K18: 420 | L18: Late night
B19: 46299 | C19: Breakfast | D19: Upma with vegetables | E19: 4 | F19: 6 | G19: 38 | H19: 4 | I19: 5 | J19: 3 | K19: 260
B20: 46299 | C20: Lunch | D20: Chole, 2 bhature, onion | E20: 2 | F20: 12 | G20: 85 | H20: 8 | I20: 22 | J20: 2 | K20: 780 | L20: Restaurant
B21: 46299 | C21: Snack | D21: Samosa (2) + chai | E21: 1 | F21: 4 | G21: 35 | H21: 2 | I21: 16 | J21: 1 | K21: 380
B22: 46299 | C22: Dinner | D22: Grilled chicken salad, soup | E22: 5 | F22: 32 | G22: 20 | H22: 6 | I22: 8 | J22: 5 | K22: 350 | L22: Home cooked
B23: 46300 | C23: Breakfast | D23: Oats porridge with banana, honey | E23: 5 | F23: 10 | G23: 55 | H23: 6 | I23: 4 | J23: 4 | K23: 320
B24: 46300 | C24: Lunch | D24: Fish curry, rice, cabbage sabzi | E24: 5 | F24: 26 | G24: 62 | H24: 5 | I24: 10 | J24: 4 | K24: 540 | L24: Home cooked
B25: 46300 | C25: Dinner | D25: Roti, dal fry, aloo gobi | E25: 4 | F25: 12 | G25: 58 | H25: 7 | I25: 8 | J25: 3 | K25: 450 | L25: Home cooked
B26: 46301 | C26: Breakfast | D26: Bread omelette (2 eggs) | E26: 3 | F26: 14 | G26: 28 | H26: 1 | I26: 12 | J26: 2 | K26: 320
B27: 46301 | C27: Lunch | D27: Biryani (mutton), raita | E27: 3 | F27: 24 | G27: 78 | H27: 3 | I27: 18 | J27: 2 | K27: 750 | L27: Ordered in
B28: 46301 | C28: Snack | D28: Cold coffee (sweetened) | E28: 2 | F28: 4 | G28: 32 | H28: 0 | I28: 6 | J28: 1 | K28: 220 | L28: Cafe
B29: 46301 | C29: Dinner | D29: Pizza (2 slices) + garlic bread | E29: 1 | F29: 14 | G29: 72 | H29: 2 | I29: 20 | J29: 1 | K29: 680 | L29: Dominos
B30: 46302 | C30: Breakfast | D30: Besan chilla with mint chutney | E30: 4 | F30: 10 | G30: 22 | H30: 4 | I30: 6 | J30: 3 | K30: 220
B31: 46302 | C31: Lunch | D31: Palak paneer, rice, dal | E31: 5 | F31: 20 | G31: 62 | H31: 8 | I31: 12 | J31: 5 | K31: 540 | L31: Home cooked
B32: 46302 | C32: Snack | D32: Sprouts chaat | E32: 5 | F32: 8 | G32: 18 | H32: 6 | I32: 2 | J32: 4 | K32: 140
B33: 46302 | C33: Dinner | D33: Khichdi with ghee, papad | E33: 4 | F33: 10 | G33: 52 | H33: 5 | I33: 10 | J33: 3 | K33: 380 | L33: Light dinner

Sheet Exercise Log
B2: Exercise Log — October 2026
B3: Log your exercises. Calories burned will be estimated by the cron job based on exercise type and duration.
B4: * Calories Burned is estimated by the cron job based on exercise type, duration, and intensity. Blue cells = you fill, white cells = cron fills.
B5: Date | C5: Exercise | D5: Duration (min) | E5: Intensity (Low/Med/High) | F5: Calories Burned * | G5: Steps | H5: Notes
B6: 46296 | C6: Morning walk | D6: 30 | E6: Low | F6: 120 | G6: 3500
B7: 46296 | C7: Push-ups, squats | D7: 15 | E7: Med | F7: 80 | G7: 0 | H7: Bodyweight circuit
B8: 46297 | C8: Running | D8: 25 | E8: High | F8: 280 | G8: 4200 | H8: Park
B9: 46298 | C9: Yoga | D9: 40 | E9: Low | F9: 100 | G9: 0 | H9: YouTube session
B10: 46299 | C10: Rest day | D10: 0 | E10: Low | F10: 0 | G10: 2000 | H10: Just walking around
B11: 46300 | C11: Cycling | D11: 45 | E11: Med | F11: 320 | G11: 0 | H11: Evening ride
B12: 46300 | C12: Stretching | D12: 10 | E12: Low | F12: 30 | G12: 0
B13: 46301 | C13: Morning walk | D13: 35 | E13: Low | F13: 140 | G13: 4000
B14: 46302 | C14: HIIT workout | D14: 20 | E14: High | F14: 250 | G14: 0 | H14: Home workout
B15: 46302 | C15: Evening walk | D15: 25 | E15: Low | F15: 100 | G15: 3000

Sheet Weight Log
B2: Weight Log — October 2026
B3: Record your weight whenever you weigh in. Feeds the weight chart and goal tracker.
B5: Goal | C5: Weight Loss
B6: Start Weight (kg) | C6: 70
B7: Target Weight (kg) | C7: 65
B8: Target Date | C8: 46326
B9: Current Weight | C9: =C18
B10: Change | C10: =C9-C6
B11: Progress | C11: =IF(C7-C6=0,0,(C9-C6)/(C7-C6))
B12: Height assumed: 1.72m for BMI calc
B14: Date | C14: Weight (kg) | D14: Change | E14: BMI
B15: 46296 | C15: 70 | D15: 0 | E15: =C15/(1.72*1.72)
B16: 46298 | C16: 69.8 | D16: =C16-C15 | E16: =C16/(1.72*1.72)
B17: 46300 | C17: 69.5 | D17: =C17-C16 | E17: =C17/(1.72*1.72)
B18: 46302 | C18: 69.6 | D18: =C18-C17 | E18: =C18/(1.72*1.72)

Sheet Calendar
B2: Health Calendar — October 2026
B3: Each day is color-coded by average healthiness score from the Food Log.
B5: Healthy (4-5) | D5: Mixed (2.5-3.9) | F5: Unhealthy (<2.5) | H5: No data
B7: Sun | C7: Mon | D7: Tue | E7: Wed | F7: Thu | G7: Fri | H7: Sat
F8: 1 | G8: 2 | H8: 3
F9: 3.5 | G9: 4 | H9: 3.7
B11: 4 | C11: 5 | D11: 6 | E11: 7 | F11: 8 | G11: 9 | H11: 10
B12: 3 | C12: 4.7 | D12: 2.2 | E12: 4.5 | F12: - | G12: - | H12: -
B14: 11 | C14: 12 | D14: 13 | E14: 14 | F14: 15 | G14: 16 | H14: 17
B15: - | C15: - | D15: - | E15: - | F15: - | G15: - | H15: -
B17: 18 | C17: 19 | D17: 20 | E17: 21 | F17: 22 | G17: 23 | H17: 24
B18: - | C18: - | D18: - | E18: - | F18: - | G18: - | H18: -
B20: 25 | C20: 26 | D20: 27 | E20: 28 | F20: 29 | G20: 30 | H20: 31
B21: - | C21: - | D21: - | E21: - | F21: - | G21: - | H21: -

Sheet Dashboard Data
B2: Dashboard Data (Auto-calculated)
B3: This tab is populated by formulas. Do not edit manually.
B5: Daily Nutrition Summary
B6: Date | C6: Avg Health Score | D6: Total Protein (g) | E6: Total Carbs (g) | F6: Total Fibre (g) | G6: Total Fat (g) | H6: Avg Vitamin Score | I6: Total Calories | J6: Meals Count
B7: 1 | C7: 46296 | D7: =IFERROR(AVERAGEIF('Food Log'!$B$8:$B$200,C7,'Food Log'!$E$8:$E$200),0) | E7: =SUMIF('Food Log'!$B$8:$B$200,C7,'Food Log'!$F$8:$F$200) | F7: =SUMIF('Food Log'!$B$8:$B$200,C7,'Food Log'!$G$8:$G$200) | G7: =SUMIF('Food Log'!$B$8:$B$200,C7,'Food Log'!$H$8:$H$200) | H7: =SUMIF('Food Log'!$B$8:$B$200,C7,'Food Log'!$I$8:$I$200) | I7: =IFERROR(AVERAGEIF('Food Log'!$B$8:$B$200,C7,'Food Log'!$J$8:$J$200),0) | J7: =SUMIF('Food Log'!$B$8:$B$200,C7,'Food Log'!$K$8:$K$200) | K7: =COUNTIF('Food Log'!$B$8:$B$200,C7)
B8: 2 | C8: 46297 | D8: =IFERROR(AVERAGEIF('Food Log'!$B$8:$B$200,C8,'Food Log'!$E$8:$E$200),0) | E8: =SUMIF('Food Log'!$B$8:$B$200,C8,'Food Log'!$F$8:$F$200) | F8: =SUMIF('Food Log'!$B$8:$B$200,C8,'Food Log'!$G$8:$G$200) | G8: =SUMIF('Food Log'!$B$8:$B$200,C8,'Food Log'!$H$8:$H$200) | H8: =SUMIF('Food Log'!$B$8:$B$200,C8,'Food Log'!$I$8:$I$200) | I8: =IFERROR(AVERAGEIF('Food Log'!$B$8:$B$200,C8,'Food Log'!$J$8:$J$200),0) | J8: =SUMIF('Food Log'!$B$8:$B$200,C8,'Food Log'!$K$8:$K$200) | K8: =COUNTIF('Food Log'!$B$8:$B$200,C8)
B9: 3 | C9: 46298 | D9: =IFERROR(AVERAGEIF('Food Log'!$B$8:$B$200,C9,'Food Log'!$E$8:$E$200),0) | E9: =SUMIF('Food Log'!$B$8:$B$200,C9,'Food Log'!$F$8:$F$200) | F9: =SUMIF('Food Log'!$B$8:$B$200,C9,'Food Log'!$G$8:$G$200) | G9: =SUMIF('Food Log'!$B$8:$B$200,C9,'Food Log'!$H$8:$H$200) | H9: =SUMIF('Food Log'!$B$8:$B$200,C9,'Food Log'!$I$8:$I$200) | I9: =IFERROR(AVERAGEIF('Food Log'!$B$8:$B$200,C9,'Food Log'!$J$8:$J$200),0) | J9: =SUMIF('Food Log'!$B$8:$B$200,C9,'Food Log'!$K$8:$K$200) | K9: =COUNTIF('Food Log'!$B$8:$B$200,C9)
B10: 4 | C10: 46299 | D10: =IFERROR(AVERAGEIF('Food Log'!$B$8:$B$200,C10,'Food Log'!$E$8:$E$200),0) | E10: =SUMIF('Food Log'!$B$8:$B$200,C10,'Food Log'!$F$8:$F$200) | F10: =SUMIF('Food Log'!$B$8:$B$200,C10,'Food Log'!$G$8:$G$200) | G10: =SUMIF('Food Log'!$B$8:$B$200,C10,'Food Log'!$H$8:$H$200) | H10: =SUMIF('Food Log'!$B$8:$B$200,C10,'Food Log'!$I$8:$I$200) | I10: =IFERROR(AVERAGEIF('Food Log'!$B$8:$B$200,C10,'Food Log'!$J$8:$J$200),0) | J10: =SUMIF('Food Log'!$B$8:$B$200,C10,'Food Log'!$K$8:$K$200) | K10: =COUNTIF('Food Log'!$B$8:$B$200,C10)
B11: 5 | C11: 46300 | D11: =IFERROR(AVERAGEIF('Food Log'!$B$8:$B$200,C11,'Food Log'!$E$8:$E$200),0) | E11: =SUMIF('Food Log'!$B$8:$B$200,C11,'Food Log'!$F$8:$F$200) | F11: =SUMIF('Food Log'!$B$8:$B$200,C11,'Food Log'!$G$8:$G$200) | G11: =SUMIF('Food Log'!$B$8:$B$200,C11,'Food Log'!$H$8:$H$200) | H11: =SUMIF('Food Log'!$B$8:$B$200,C11,'Food Log'!$I$8:$I$200) | I11: =IFERROR(AVERAGEIF('Food Log'!$B$8:$B$200,C11,'Food Log'!$J$8:$J$200),0) | J11: =SUMIF('Food Log'!$B$8:$B$200,C11,'Food Log'!$K$8:$K$200) | K11: =COUNTIF('Food Log'!$B$8:$B$200,C11)
B12: 6 | C12: 46301 | D12: =IFERROR(AVERAGEIF('Food Log'!$B$8:$B$200,C12,'Food Log'!$E$8:$E$200),0) | E12: =SUMIF('Food Log'!$B$8:$B$200,C12,'Food Log'!$F$8:$F$200) | F12: =SUMIF('Food Log'!$B$8:$B$200,C12,'Food Log'!$G$8:$G$200) | G12: =SUMIF('Food Log'!$B$8:$B$200,C12,'Food Log'!$H$8:$H$200) | H12: =SUMIF('Food Log'!$B$8:$B$200,C12,'Food Log'!$I$8:$I$200) | I12: =IFERROR(AVERAGEIF('Food Log'!$B$8:$B$200,C12,'Food Log'!$J$8:$J$200),0) | J12: =SUMIF('Food Log'!$B$8:$B$200,C12,'Food Log'!$K$8:$K$200) | K12: =COUNTIF('Food Log'!$B$8:$B$200,C12)
B13: 7 | C13: 46302 | D13: =IFERROR(AVERAGEIF('Food Log'!$B$8:$B$200,C13,'Food Log'!$E$8:$E$200),0) | E13: =SUMIF('Food Log'!$B$8:$B$200,C13,'Food Log'!$F$8:$F$200) | F13: =SUMIF('Food Log'!$B$8:$B$200,C13,'Food Log'!$G$8:$G$200) | G13: =SUMIF('Food Log'!$B$8:$B$200,C13,'Food Log'!$H$8:$H$200) | H13: =SUMIF('Food Log'!$B$8:$B$200,C13,'Food Log'!$I$8:$I$200) | I13: =IFERROR(AVERAGEIF('Food Log'!$B$8:$B$200,C13,'Food Log'!$J$8:$J$200),0) | J13: =SUMIF('Food Log'!$B$8:$B$200,C13,'Food Log'!$K$8:$K$200) | K13: =COUNTIF('Food Log'!$B$8:$B$200,C13)
B14: 8 | C14: 46303 | D14: =IFERROR(AVERAGEIF('Food Log'!$B$8:$B$200,C14,'Food Log'!$E$8:$E$200),0) | E14: =SUMIF('Food Log'!$B$8:$B$200,C14,'Food Log'!$F$8:$F$200) | F14: =SUMIF('Food Log'!$B$8:$B$200,C14,'Food Log'!$G$8:$G$200) | G14: =SUMIF('Food Log'!$B$8:$B$200,C14,'Food Log'!$H$8:$H$200) | H14: =SUMIF('Food Log'!$B$8:$B$200,C14,'Food Log'!$I$8:$I$200) | I14: =IFERROR(AVERAGEIF('Food Log'!$B$8:$B$200,C14,'Food Log'!$J$8:$J$200),0) | J14: =SUMIF('Food Log'!$B$8:$B$200,C14,'Food Log'!$K$8:$K$200) | K14: =COUNTIF('Food Log'!$B$8:$B$200,C14)
B15: 9 | C15: 46304 | D15: =IFERROR(AVERAGEIF('Food Log'!$B$8:$B$200,C15,'Food Log'!$E$8:$E$200),0) | E15: =SUMIF('Food Log'!$B$8:$B$200,C15,'Food Log'!$F$8:$F$200) | F15: =SUMIF('Food Log'!$B$8:$B$200,C15,'Food Log'!$G$8:$G$200) | G15: =SUMIF('Food Log'!$B$8:$B$200,C15,'Food Log'!$H$8:$H$200) | H15: =SUMIF('Food Log'!$B$8:$B$200,C15,'Food Log'!$I$8:$I$200) | I15: =IFERROR(AVERAGEIF('Food Log'!$B$8:$B$200,C15,'Food Log'!$J$8:$J$200),0) | J15: =SUMIF('Food Log'!$B$8:$B$200,C15,'Food Log'!$K$8:$K$200) | K15: =COUNTIF('Food Log'!$B$8:$B$200,C15)
B16: 10 | C16: 46305 | D16: =IFERROR(AVERAGEIF('Food Log'!$B$8:$B$200,C16,'Food Log'!$E$8:$E$200),0) | E16: =SUMIF('Food Log'!$B$8:$B$200,C16,'Food Log'!$F$8:$F$200) | F16: =SUMIF('Food Log'!$B$8:$B$200,C16,'Food Log'!$G$8:$G$200) | G16: =SUMIF('Food Log'!$B$8:$B$200,C16,'Food Log'!$H$8:$H$200) | H16: =SUMIF('Food Log'!$B$8:$B$200,C16,'Food Log'!$I$8:$I$200) | I16: =IFERROR(AVERAGEIF('Food Log'!$B$8:$B$200,C16,'Food Log'!$J$8:$J$200),0) | J16: =SUMIF('Food Log'!$B$8:$B$200,C16,'Food Log'!$K$8:$K$200) | K16: =COUNTIF('Food Log'!$B$8:$B$200,C16)
B17: 11 | C17: 46306 | D17: =IFERROR(AVERAGEIF('Food Log'!$B$8:$B$200,C17,'Food Log'!$E$8:$E$200),0) | E17: =SUMIF('Food Log'!$B$8:$B$200,C17,'Food Log'!$F$8:$F$200) | F17: =SUMIF('Food Log'!$B$8:$B$200,C17,'Food Log'!$G$8:$G$200) | G17: =SUMIF('Food Log'!$B$8:$B$200,C17,'Food Log'!$H$8:$H$200) | H17: =SUMIF('Food Log'!$B$8:$B$200,C17,'Food Log'!$I$8:$I$200) | I17: =IFERROR(AVERAGEIF('Food Log'!$B$8:$B$200,C17,'Food Log'!$J$8:$J$200),0) | J17: =SUMIF('Food Log'!$B$8:$B$200,C17,'Food Log'!$K$8:$K$200) | K17: =COUNTIF('Food Log'!$B$8:$B$200,C17)
B18: 12 | C18: 46307 | D18: =IFERROR(AVERAGEIF('Food Log'!$B$8:$B$200,C18,'Food Log'!$E$8:$E$200),0) | E18: =SUMIF('Food Log'!$B$8:$B$200,C18,'Food Log'!$F$8:$F$200) | F18: =SUMIF('Food Log'!$B$8:$B$200,C18,'Food Log'!$G$8:$G$200) | G18: =SUMIF('Food Log'!$B$8:$B$200,C18,'Food Log'!$H$8:$H$200) | H18: =SUMIF('Food Log'!$B$8:$B$200,C18,'Food Log'!$I$8:$I$200) | I18: =IFERROR(AVERAGEIF('Food Log'!$B$8:$B$200,C18,'Food Log'!$J$8:$J$200),0) | J18: =SUMIF('Food Log'!$B$8:$B$200,C18,'Food Log'!$K$8:$K$200) | K18: =COUNTIF('Food Log'!$B$8:$B$200,C18)
... B37: 31 | C37: 46326 | D37: =IFERROR(AVERAGEIF('Food Log'!$B$8:$B$200,C37,'Food Log'!$E$8:$E$200),0) | E37: =SUMIF('Food Log'!$B$8:$B$200,C37,'Food Log'!$F$8:$F$200) | F37: =SUMIF('Food Log'!$B$8:$B$200,C37,'Food Log'!$G$8:$G$200) | G37: =SUMIF('Food Log'!$B$8:$B$200,C37,'Food Log'!$H$8:$H$200) | H37: =SUMIF('Food Log'!$B$8:$B$200,C37,'Food Log'!$I$8:$I$200) | I37: =IFERROR(AVERAGEIF('Food Log'!$B$8:$B$200,C37,'Food Log'!$J$8:$J$200),0) | J37: =SUMIF('Food Log'!$B$8:$B$200,C37,'Food Log'!$K$8:$K$200) | K37: =COUNTIF('Food Log'!$B$8:$B$200,C37)
B40: Daily Exercise Summary
B41: Date | C41: Total Cal Burned | D41: Total Duration (min) | E41: Total Steps | F41: Sessions
B42: 1 | C42: 46296 | D42: =SUMIF('Exercise Log'!$B$6:$B$100,C42,'Exercise Log'!$F$6:$F$100) | E42: =SUMIF('Exercise Log'!$B$6:$B$100,C42,'Exercise Log'!$D$6:$D$100) | F42: =SUMIF('Exercise Log'!$B$6:$B$100,C42,'Exercise Log'!$G$6:$G$100) | G42: =COUNTIF('Exercise Log'!$B$6:$B$100,C42)
B43: 2 | C43: 46297 | D43: =SUMIF('Exercise Log'!$B$6:$B$100,C43,'Exercise Log'!$F$6:$F$100) | E43: =SUMIF('Exercise Log'!$B$6:$B$100,C43,'Exercise Log'!$D$6:$D$100) | F43: =SUMIF('Exercise Log'!$B$6:$B$100,C43,'Exercise Log'!$G$6:$G$100) | G43: =COUNTIF('Exercise Log'!$B$6:$B$100,C43)
B44: 3 | C44: 46298 | D44: =SUMIF('Exercise Log'!$B$6:$B$100,C44,'Exercise Log'!$F$6:$F$100) | E44: =SUMIF('Exercise Log'!$B$6:$B$100,C44,'Exercise Log'!$D$6:$D$100) | F44: =SUMIF('Exercise Log'!$B$6:$B$100,C44,'Exercise Log'!$G$6:$G$100) | G44: =COUNTIF('Exercise Log'!$B$6:$B$100,C44)
B45: 4 | C45: 46299 | D45: =SUMIF('Exercise Log'!$B$6:$B$100,C45,'Exercise Log'!$F$6:$F$100) | E45: =SUMIF('Exercise Log'!$B$6:$B$100,C45,'Exercise Log'!$D$6:$D$100) | F45: =SUMIF('Exercise Log'!$B$6:$B$100,C45,'Exercise Log'!$G$6:$G$100) | G45: =COUNTIF('Exercise Log'!$B$6:$B$100,C45)
B46: 5 | C46: 46300 | D46: =SUMIF('Exercise Log'!$B$6:$B$100,C46,'Exercise Log'!$F$6:$F$100) | E46: =SUMIF('Exercise Log'!$B$6:$B$100,C46,'Exercise Log'!$D$6:$D$100) | F46: =SUMIF('Exercise Log'!$B$6:$B$100,C46,'Exercise Log'!$G$6:$G$100) | G46: =COUNTIF('Exercise Log'!$B$6:$B$100,C46)
B47: 6 | C47: 46301 | D47: =SUMIF('Exercise Log'!$B$6:$B$100,C47,'Exercise Log'!$F$6:$F$100) | E47: =SUMIF('Exercise Log'!$B$6:$B$100,C47,'Exercise Log'!$D$6:$D$100) | F47: =SUMIF('Exercise Log'!$B$6:$B$100,C47,'Exercise Log'!$G$6:$G$100) | G47: =COUNTIF('Exercise Log'!$B$6:$B$100,C47)
B48: 7 | C48: 46302 | D48: =SUMIF('Exercise Log'!$B$6:$B$100,C48,'Exercise Log'!$F$6:$F$100) | E48: =SUMIF('Exercise Log'!$B$6:$B$100,C48,'Exercise Log'!$D$6:$D$100) | F48: =SUMIF('Exercise Log'!$B$6:$B$100,C48,'Exercise Log'!$G$6:$G$100) | G48: =COUNTIF('Exercise Log'!$B$6:$B$100,C48)
B49: 8 | C49: 46303 | D49: =SUMIF('Exercise Log'!$B$6:$B$100,C49,'Exercise Log'!$F$6:$F$100) | E49: =SUMIF('Exercise Log'!$B$6:$B$100,C49,'Exercise Log'!$D$6:$D$100) | F49: =SUMIF('Exercise Log'!$B$6:$B$100,C49,'Exercise Log'!$G$6:$G$100) | G49: =COUNTIF('Exercise Log'!$B$6:$B$100,C49)
B50: 9 | C50: 46304 | D50: =SUMIF('Exercise Log'!$B$6:$B$100,C50,'Exercise Log'!$F$6:$F$100) | E50: =SUMIF('Exercise Log'!$B$6:$B$100,C50,'Exercise Log'!$D$6:$D$100) | F50: =SUMIF('Exercise Log'!$B$6:$B$100,C50,'Exercise Log'!$G$6:$G$100) | G50: =COUNTIF('Exercise Log'!$B$6:$B$100,C50)
B51: 10 | C51: 46305 | D51: =SUMIF('Exercise Log'!$B$6:$B$100,C51,'Exercise Log'!$F$6:$F$100) | E51: =SUMIF('Exercise Log'!$B$6:$B$100,C51,'Exercise Log'!$D$6:$D$100) | F51: =SUMIF('Exercise Log'!$B$6:$B$100,C51,'Exercise Log'!$G$6:$G$100) | G51: =COUNTIF('Exercise Log'!$B$6:$B$100,C51)
B52: 11 | C52: 46306 | D52: =SUMIF('Exercise Log'!$B$6:$B$100,C52,'Exercise Log'!$F$6:$F$100) | E52: =SUMIF('Exercise Log'!$B$6:$B$100,C52,'Exercise Log'!$D$6:$D$100) | F52: =SUMIF('Exercise Log'!$B$6:$B$100,C52,'Exercise Log'!$G$6:$G$100) | G52: =COUNTIF('Exercise Log'!$B$6:$B$100,C52)
B53: 12 | C53: 46307 | D53: =SUMIF('Exercise Log'!$B$6:$B$100,C53,'Exercise Log'!$F$6:$F$100) | E53: =SUMIF('Exercise Log'!$B$6:$B$100,C53,'Exercise Log'!$D$6:$D$100) | F53: =SUMIF('Exercise Log'!$B$6:$B$100,C53,'Exercise Log'!$G$6:$G$100) | G53: =COUNTIF('Exercise Log'!$B$6:$B$100,C53)
... B72: 31 | C72: 46326 | D72: =SUMIF('Exercise Log'!$B$6:$B$100,C72,'Exercise Log'!$F$6:$F$100) | E72: =SUMIF('Exercise Log'!$B$6:$B$100,C72,'Exercise Log'!$D$6:$D$100) | F72: =SUMIF('Exercise Log'!$B$6:$B$100,C72,'Exercise Log'!$G$6:$G$100) | G72: =COUNTIF('Exercise Log'!$B$6:$B$100,C72)
B75: Nutrition vs Ideal (Monthly Avg)
B76: Nutrient | C76: Your Avg (per day) | D76: Ideal (per day) | E76: % of Ideal
B77: 1 | C77: Protein (g) | D77: =IFERROR(AVERAGEIF(E7:E37,">"&0),0) | E77: 55 | F77: =IFERROR(D77/E77,0)
B78: 2 | C78: Carbs (g) | D78: =IFERROR(AVERAGEIF(F7:F37,">"&0),0) | E78: 275 | F78: =IFERROR(D78/E78,0)
B79: 3 | C79: Fibre (g) | D79: =IFERROR(AVERAGEIF(G7:G37,">"&0),0) | E79: 30 | F79: =IFERROR(D79/E79,0)
B80: 4 | C80: Fat (g) | D80: =IFERROR(AVERAGEIF(H7:H37,">"&0),0) | E80: 65 | F80: =IFERROR(D80/E80,0)
B81: 5 | C81: Calories (kcal) | D81: =IFERROR(AVERAGEIF(J7:J37,">"&0),0) | E81: 2000 | F81: =IFERROR(D81/E81,0)
B83: Meal Healthiness Distribution
...
